Workbook

Sheet Hypothèses
A1: Code Galsen — Hypothèses business
A3: Bleu = input modifiable · Noir = calculé
A5: PRODUIT
A6: Prix Pass Réussite (unitaire) | B6: 4900 | C6: FCFA
A7: Durée Pass | B7: 90 | C7: jours
A8: Commission PayDunya | B8: 0.025 | C8: %
A9: Coût SMS OTP unitaire | B9: 30 | C9: FCFA
A10: Coût Africa's Talking init | B10: 5000 | C10: FCFA (crédits)
A12: ACQUISITION / FUNNEL
A13: Trafic mensuel cible mois 1 | B13: 500 | C13: visiteurs
A14: Taux inscription (visit → user) | B14: 0.3 | C14: %
A15: Taux activation pass (user → payant) | B15: 0.15 | C15: %
A16: Croissance mensuelle MoM | B16: 0.4 | C16: % (organique + WoM)
A17: Churn re-pass à J+90 | B17: 0.2 | C17: % (pass renouvelé)
A19: OPS / RH
A20: Salaire dev solo (mois) | B20: 0 | C20: FCFA (founder unpaid)
A21: Honoraires juriste (unique) | B21: 75000 | C21: FCFA
A22: Studio audio Wolof (unique) | B22: 350000 | C22: FCFA (30 fiches)
A23: Marketing soft launch | B23: 50000 | C23: FCFA
A24: Domaine + DNS annuel | B24: 15000 | C24: FCFA/an

Sheet Budget MVP 90j
A1: Budget MVP — 90 jours (J1 → J90)
A3: Poste | B3: Catégorie | C3: Montant FCFA | D3: Notes
A4: Infra & SaaS
A5: Supabase Free → Pro mois 2-3 | B5: Infra | C5: 0 | D5: Free tier MVP. Pro = 25 USD ≈ 15 000 FCFA si dépassement
A6: Vercel Hobby | B6: Infra | C6: 0 | D6: Free tier suffit MVP
A7: Bunny.net CDN | B7: Infra | C7: 6000 | D7: 0.005 USD/Go · ~1 000 users × 15 Mo × 3 mois
A8: Sentry Free | B8: Infra | C8: 0 | D8: Free tier 5k events/mois
A9: Plausible self-hosted | B9: Infra | C9: 0 | D9: ou Cloud 9 USD/mois si fainéant
A10: Upstash Redis Free | B10: Infra | C10: 0 | D10: Free 10k commands/jour suffit rate-limit
A11: Sous-total Infra & SaaS | C11: =SUM(C5:C10) -> 6000
A13: Communications
A14: Africa's Talking SMS (~3 000 SMS) | B14: Comm | C14: 90000 | D14: 30 FCFA × 3 000 OTP estimés sur 90j
A15: WhatsApp Business API setup | B15: Comm | C15: 0 | D15: Free + envoi marketing 12 FCFA/conversation après free tier
A16: PayDunya commission (75 ventes × 122) | B16: Comm | C16: 9150 | D16: 2.5% × 4 900 × 75
A17: Sous-total Communications | C17: =SUM(C14:C16) -> 99150
A19: Contenu
A20: Studio audio Wolof (30 fiches MVP) | B20: Contenu | C20: =Hypothèses!B22 -> 350000 | D20: Voix-off + relecture. À reporter si budget refusé
A21: Dataset questions UEMOA (achat ou rédaction) | B21: Contenu | C21: 50000 | D21: Soit achat dataset existant, soit rédaction freelance
A22: Illustrations / photos panneaux UEMOA | B22: Contenu | C22: 25000 | D22: Banque images locale ou shoot perso à Dakar
A23: Sous-total Contenu | C23: =SUM(C20:C22) -> 425000
A25: Légal & Conformité
A26: Consultation juriste sénégalais | B26: Légal | C26: =Hypothèses!B21 -> 75000 | D26: CGU + CDP + ARTP compliance
A27: Déclaration CDP (commission protection données) | B27: Légal | C27: 25000 | D27: Procédure obligatoire collecte phone
A28: Sous-total Légal & Conformité | C28: =SUM(C26:C27) -> 100000
A30: Domaine & Marque
A31: Domaine .com (1 an) | B31: Marque | C31: 8000 | D31: ou .sn ≈ 30 000 FCFA
A32: Identité visuelle minimale | B32: Marque | C32: 30000 | D32: Logo + 1 page brand mini
A33: Sous-total Domaine & Marque | C33: =SUM(C31:C32) -> 38000
A35: Launch & Marketing
A36: Campagne soft launch WhatsApp Dakar | B36: Launch | C36: =Hypothèses!B23 -> 50000 | D36: Targeting auto-écoles partenaires
A37: 3 partenariats auto-écoles (kit promo papier) | B37: Launch | C37: 20000 | D37: Flyers A6 imprimés × 500
A38: Posters publicitaires lieux passage permis | B38: Launch | C38: 15000 | D38: A3 × 20 emplacements stratégiques
A39: Sous-total Launch & Marketing | C39: =SUM(C36:C38) -> 85000
A41: RH
A42: Salaire dev solo (3 mois) | B42: RH | C42: =3*Hypothèses!B20 -> 0 | D42: Founder unpaid si bootstrap, sinon ~600k FCFA/mois marché Dakar
A43: Sous-total RH | C43: =SUM(C42) -> 0
A45: TOTAL MVP 90 jours | C45: =C11+C17+C23+C28+C33+C39+C43 -> 753150
A48: REVENUS PRÉVISIONNELS MVP (90j)
A49: Users inscrits (cible) | C49: 500
A50: Taux activation pass | C50: =Hypothèses!B15 -> 0.15
...

Sheet Projection 12 mois
A1: Projection 12 mois post-launch
A3: Métrique | B3: M1 | C3: M2 | D3: M3 | E3: M4 | F3: M5 | G3: M6 | H3: M7 | I3: M8 | J3: M9 | K3: M10 | L3: M11 | M3: M12 | N3: Total 12m
A4: Users inscrits (cumul) | B4: 500 | C4: =ROUND(B4*(1+Hypothèses!B16), 0) -> 700 | D4: =ROUND(C4*(1+Hypothèses!B16), 0) -> 980 | E4: =ROUND(D4*(1+Hypothèses!B16), 0) -> 1372 | F4: =ROUND(E4*(1+Hypothèses!B16), 0) -> 1921 | G4: =ROUND(F4*(1+Hypothèses!B16), 0) -> 2689 | H4: =ROUND(G4*(1+Hypothèses!B16), 0) -> 3765 | I4: =ROUND(H4*(1+Hypothèses!B16), 0) -> 5271 | J4: =ROUND(I4*(1+Hypothèses!B16), 0) -> 7379 | K4: =ROUND(J4*(1+Hypothèses!B16), 0) -> 10331 | L4: =ROUND(K4*(1+Hypothèses!B16), 0) -> 14463 | M4: =ROUND(L4*(1+Hypothèses!B16), 0) -> 20248
A5: Pass activés (nouveaux mensuels) | B5: =ROUND(B4*Hypothèses!B15, 0) -> 75 | C5: =ROUND((C4-B4)*Hypothèses!B15, 0) -> 30 | D5: =ROUND((D4-C4)*Hypothèses!B15, 0) -> 42 | E5: =ROUND((E4-D4)*Hypothèses!B15, 0) -> 59 | F5: =ROUND((F4-E4)*Hypothèses!B15, 0) -> 82 | G5: =ROUND((G4-F4)*Hypothèses!B15, 0) -> 115 | H5: =ROUND((H4-G4)*Hypothèses!B15, 0) -> 161 | I5: =ROUND((I4-H4)*Hypothèses!B15, 0) -> 226 | J5: =ROUND((J4-I4)*Hypothèses!B15, 0) -> 316 | K5: =ROUND((K4-J4)*Hypothèses!B15, 0) -> 443 | L5: =ROUND((L4-K4)*Hypothèses!B15, 0) -> 620 | M5: =ROUND((M4-L4)*Hypothèses!B15, 0) -> 868 | N5: =SUM(B5:M5) -> 3037
A6: Revenu mensuel | B6: =B5*Hypothèses!B6 -> 367500 | C6: =C5*Hypothèses!B6 -> 147000 | D6: =D5*Hypothèses!B6 -> 205800 | E6: =E5*Hypothèses!B6 -> 289100 | F6: =F5*Hypothèses!B6 -> 401800 | G6: =G5*Hypothèses!B6 -> 563500 | H6: =H5*Hypothèses!B6 -> 788900 | I6: =I5*Hypothèses!B6 -> 1107400 | J6: =J5*Hypothèses!B6 -> 1548400 | K6: =K5*Hypothèses!B6 -> 2170700 | L6: =L5*Hypothèses!B6 -> 3038000 | M6: =M5*Hypothèses!B6 -> 4253200 | N6: =SUM(B6:M6) -> 14881300
A7: Coûts mensuels (infra + comm) | B7: =15000+B4*Hypothèses!B14*0.3 -> 15045 | C7: =15000+C4*Hypothèses!B14*0.3 -> 15063 | D7: =15000+D4*Hypothèses!B14*0.3 -> 15088.2 | E7: =15000+E4*Hypothèses!B14*0.3 -> 15123.48 | F7: =15000+F4*Hypothèses!B14*0.3 -> 15172.89 | G7: =15000+G4*Hypothèses!B14*0.3 -> 15242.01 | H7: =15000+H4*Hypothèses!B14*0.3 -> 15338.85 | I7: =15000+I4*Hypothèses!B14*0.3 -> 15474.39 | J7: =15000+J4*Hypothèses!B14*0.3 -> 15664.11 | K7: =15000+K4*Hypothèses!B14*0.3 -> 15929.79 | L7: =15000+L4*Hypothèses!B14*0.3 -> 16301.67 | M7: =15000+M4*Hypothèses!B14*0.3 -> 16822.32 | N7: =SUM(B7:M7) -> 186265.71
A8: Marge brute mensuelle | B8: =B6-B7 -> 352455 | C8: =C6-C7 -> 131937 | D8: =D6-D7 -> 190711.8 | E8: =E6-E7 -> 273976.52 | F8: =F6-F7 -> 386627.11 | G8: =G6-G7 -> 548257.99 | H8: =H6-H7 -> 773561.15 | I8: =I6-I7 -> 1091925.6 | ... M8: =M6-M7 -> 4236377.7 | N8: =SUM(B8:M8) -> 14695034
A9: Marge cumulée | B9: =B8 -> 352455 | C9: =B9+C8 -> 484392 | D9: =C9+D8 -> 675103.8 | E9: =D9+E8 -> 949080.32 | F9: =E9+F8 -> 1335707.4 | G9: =F9+G8 -> 1883965.4 | H9: =G9+H8 -> 2657526.6 | I9: =H9+I8 -> 3749452.2 | J9: =I9+J8 -> 5282188.1 | ... M9: =L9+M8 -> 14695034 | N9: =M9 -> 14695034
A11: Notes :
A12: • Croissance MoM = paramètre 'Hypothèses!B16'. 40% est optimiste mais réaliste en bouche-à-oreille auto-école.
A13: • Pass 90 jours = on n'inclut pas le re-pass dans la projection M1-M3 (cycle pas terminé).
A14: • Coûts mensuels = infra (15k FCFA mini Vercel+CDN+Supabase Pro si dépassement) + SMS prorata users.
A15: • Marge cumulée M12 = trésorerie disponible pour V2 (Stripe Connect diaspora, codes B2B2C, etc.).
A16: • Modèle exclut salaire dev. Si dev rémunéré 600k FCFA/mois, soustraire 7.2M FCFA sur 12m.
